Traceback (most recent call last):
  File "/usr/lib/python3/dist-packages/pkg_resources/__init__.py", line 2859, in get_entry_map
    ep_map = self._ep_map
  File "/usr/lib/python3/dist-packages/pkg_resources/__init__.py", line 2817, in __getattr__
    raise AttributeError(attr)
AttributeError: _ep_map

During handling of the above exception, another exception occurred:

Traceback (most recent call last):
  File "/usr/local/bin/multiqc", line 5, in <module>
    from multiqc.__main__ import run_multiqc
  File "/usr/local/lib/python3.8/dist-packages/multiqc/__init__.py", line 16, in <module>
    from .multiqc import run
  File "/usr/local/lib/python3.8/dist-packages/multiqc/multiqc.py", line 30, in <module>
    from .plots import table
  File "/usr/local/lib/python3.8/dist-packages/multiqc/plots/table.py", line 9, in <module>
    from multiqc.plots import beeswarm, table_object
  File "/usr/local/lib/python3.8/dist-packages/multiqc/plots/beeswarm.py", line 8, in <module>
    from multiqc.plots import table_object
  File "/usr/local/lib/python3.8/dist-packages/multiqc/plots/table_object.py", line 9, in <module>
    from multiqc.utils import config, report
  File "/usr/local/lib/python3.8/dist-packages/multiqc/utils/config.py", line 67, in <module>
    for entry_point in pkg_resources.iter_entry_points("multiqc.modules.v1"):
  File "/usr/lib/python3/dist-packages/pkg_resources/__init__.py", line 657, in <genexpr>
    for entry in dist.get_entry_map(group).values()
  File "/usr/lib/python3/dist-packages/pkg_resources/__init__.py", line 2861, in get_entry_map
    ep_map = self._ep_map = EntryPoint.parse_map(
  File "/usr/lib/python3/dist-packages/pkg_resources/__init__.py", line 2529, in parse_map
    for group, lines in data:
  File "/usr/lib/python3/dist-packages/pkg_resources/__init__.py", line 3201, in split_sections
    for line in yield_lines(s):
  File "/usr/lib/python3/dist-packages/pkg_resources/__init__.py", line 2389, in yield_lines
    for ss in strs:
  File "/usr/lib/python3/dist-packages/pkg_resources/__init__.py", line 2769, in _get_metadata
    for line in self.get_metadata_lines(name):
  File "/usr/lib/python3/dist-packages/pkg_resources/__init__.py", line 1433, in get_metadata_lines
    return yield_lines(self.get_metadata(name))
  File "/usr/lib/python3/dist-packages/pkg_resources/__init__.py", line 1421, in get_metadata
    value = self._get(path)
  File "/usr/lib/python3/dist-packages/pkg_resources/__init__.py", line 1617, in _get
    with open(path, 'rb') as stream:
PermissionError: [Errno 13] Permission denied: '/usr/local/lib/python3.8/dist-packages/numpy-1.24.1.dist-info/entry_points.txt'

real	0m0.745s
user	0m0.704s
sys	0m0.042s
